Workbook

Sheet Parse Table
A1: Compiler Construction - Project Phase 2 - LL(1) Parsing Table M (non-terminals x terminals)
A2: Cell = production number k (apply it: push right side R->L) | Pop = empty box, token in FOLLOW(A) or $ -> discard A from the stack | Scan = empty box, token not in FIRST(A) U FOLLOW(A) -> discard the token from the input. Production numbers refer to the "Productions" sheet.
A4: M | B4: Adadi | C4: Ashriya | D4: Harf | E4: Matn | F4: Mantiqi | G4: Marqazi | H4: for | I4: while | J4: Agar | K4: Wagarna | L4: ID | M4: NUM | N4: ( | O4: ) | P4: { | Q4: } | R4: , | S4: :: | T4: := | U4: == | V4: < | W4: > | X4: <= | Y4: >= | Z4: != | AA4: <> | AB4: + | AC4: - | AD4: * | AE4: / | AF4: $ | AH4: Productions placed | AI4: Pop boxes | AJ4: Scan boxes | AK4: Row total
A5: Program | B5: 1 | C5: 2 | D5: 3 | E5: 4 | F5: 5 | G5: Scan | H5: Scan | I5: Scan | J5: Scan | K5: Scan | L5: Scan | M5: Scan | N5: Scan | O5: Scan | P5: Scan | Q5: Scan | R5: Scan | S5: Scan | T5: Scan | U5: Scan | V5: Scan | W5: Scan | X5: Scan | Y5: Scan | Z5: Scan | AA5: Scan | AB5: Scan | AC5: Scan | AD5: Scan | AE5: Scan | AF5: Pop | AH5: =COUNT($B5:$AF5) -> 5 | AI5: =COUNTIF($B5:$AF5,"Pop") -> 1 | AJ5: =COUNTIF($B5:$AF5,"Scan") -> 25 | AK5: =SUM(AH5:AJ5) -> 31
A6: ProgTail | B6: Scan | C6: Scan | D6: Scan | E6: Scan | F6: Scan | G6: 6 | H6: Scan | I6: Scan | J6: Scan | K6: Scan | L6: 7 | M6: Scan | N6: Scan | O6: Scan | P6: Scan | Q6: Scan | R6: Scan | S6: Scan | T6: Scan | U6: Scan | V6: Scan | W6: Scan | X6: Scan | Y6: Scan | Z6: Scan | AA6: Scan | AB6: Scan | AC6: Scan | AD6: Scan | AE6: Scan | AF6: Pop | AH6: =COUNT($B6:$AF6) -> 2 | AI6: =COUNTIF($B6:$AF6,"Pop") -> 1 | AJ6: =COUNTIF($B6:$AF6,"Scan") -> 28 | AK6: =SUM(AH6:AJ6) -> 31
A7: FuncRest | B7: Scan | C7: Scan | D7: Scan | E7: Scan | F7: Scan | G7: Scan | H7: Scan | I7: Scan | J7: Scan | K7: Scan | L7: 8 | M7: Scan | N7: Scan | O7: Scan | P7: Scan | Q7: Scan | R7: Scan | S7: Scan | T7: Scan | U7: Scan | V7: Scan | W7: Scan | X7: Scan | Y7: Scan | Z7: Scan | AA7: Scan | AB7: Scan | AC7: Scan | AD7: Scan | AE7: Scan | AF7: Pop | AH7: =COUNT($B7:$AF7) -> 1 | AI7: =COUNTIF($B7:$AF7,"Pop") -> 1 | AJ7: =COUNTIF($B7:$AF7,"Scan") -> 29 | AK7: =SUM(AH7:AJ7) -> 31
A8: ArgList | B8: 9 | C8: 9 | D8: 9 | E8: 9 | F8: 9 | G8: Scan | H8: Scan | I8: Scan | J8: Scan | K8: Scan | L8: Scan | M8: Scan | N8: Scan | O8: Pop | P8: Scan | Q8: Scan | R8: Scan | S8: Scan | T8: Scan | U8: Scan | V8: Scan | W8: Scan | X8: Scan | Y8: Scan | Z8: Scan | AA8: Scan | AB8: Scan | AC8: Scan | AD8: Scan | AE8: Scan | AF8: Pop | AH8: =COUNT($B8:$AF8) -> 5 | AI8: =COUNTIF($B8:$AF8,"Pop") -> 2 | AJ8: =COUNTIF($B8:$AF8,"Scan") -> 24 | AK8: =SUM(AH8:AJ8) -> 31
A9: ArgList' | B9: Scan | C9: Scan | D9: Scan | E9: Scan | F9: Scan | G9: Scan | H9: Scan | I9: Scan | J9: Scan | K9: Scan | L9: Scan | M9: Scan | N9: Scan | O9: 11 | P9: Scan | Q9: Scan | R9: 10 | S9: Scan | T9: Scan | U9: Scan | V9: Scan | W9: Scan | X9: Scan | Y9: Scan | Z9: Scan | AA9: Scan | AB9: Scan | AC9: Scan | AD9: Scan | AE9: Scan | AF9: Pop | AH9: =COUNT($B9:$AF9) -> 2 | AI9: =COUNTIF($B9:$AF9,"Pop") -> 1 | AJ9: =COUNTIF($B9:$AF9,"Scan") -> 28 | AK9: =SUM(AH9:AJ9) -> 31
A10: Arg | B10: 12 | C10: 12 | D10: 12 | E10: 12 | F10: 12 | G10: Scan | H10: Scan | I10: Scan | J10: Scan | K10: Scan | L10: Scan | M10: Scan | N10: Scan | O10: Pop | P10: Scan | Q10: Scan | R10: Pop | S10: Scan | T10: Scan | U10: Scan | V10: Scan | W10: Scan | X10: Scan | Y10: Scan | Z10: Scan | AA10: Scan | AB10: Scan | AC10: Scan | AD10: Scan | AE10: Scan | AF10: Pop | AH10: =COUNT($B10:$AF10) -> 5 | AI10: =COUNTIF($B10:$AF10,"Pop") -> 3 | AJ10: =COUNTIF($B10:$AF10,"Scan") -> 23 | AK10: =SUM(AH10:AJ10) -> 31
A11: Declaration | B11: 13 | C11: 13 | D11: 13 | E11: 13 | F11: 13 | G11: Scan | H11: Pop | I11: Pop | J11: Pop | K11: Scan | L11: Pop | M11: Pop | N11: Pop | O11: Scan | P11: Pop | Q11: Pop | R11: Scan | S11: Pop | T11: Scan | U11: Scan | V11: Scan | W11: Scan | X11: Scan | Y11: Scan | Z11: Scan | AA11: Scan | AB11: Scan | AC11: Scan | AD11: Scan | AE11: Scan | AF11: Pop | AH11: =COUNT($B11:$AF11) -> 5 | AI11: =COUNTIF($B11:$AF11,"Pop") -> 10 | AJ11: =COUNTIF($B11:$AF11,"Scan") -> 16 | AK11: =SUM(AH11:AJ11) -> 31
A12: IdentList | B12: Scan | C12: Scan | D12: Scan | E12: Scan | F12: Scan | G12: Scan | H12: Scan | I12: Scan | J12: Scan | K12: Scan | L12: 14 | M12: Scan | N12: Scan | O12: Scan | P12: Scan | Q12: Scan | R12: Scan | S12: Pop | T12: Scan | U12: Scan | V12: Scan | W12: Scan | X12: Scan | Y12: Scan | Z12: Scan | AA12: Scan | AB12: Scan | AC12: Scan | AD12: Scan | AE12: Scan | AF12: Pop | AH12: =COUNT($B12:$AF12) -> 1 | AI12: =COUNTIF($B12:$AF12,"Pop") -> 2 | AJ12: =COUNTIF($B12:$AF12,"Scan") -> 28 | AK12: =SUM(AH12:AJ12) -> 31
A13: IdentList' | B13: Scan | C13: Scan | D13: Scan | E13: Scan | F13: Scan | G13: Scan | H13: Scan | I13: Scan | J13: Scan | K13: Scan | L13: Scan | M13: Scan | N13: Scan | O13: Scan | P13: Scan | Q13: Scan | R13: 15 | S13: 16 | T13: Scan | U13: Scan | V13: Scan | W13: Scan | X13: Scan | Y13: Scan | Z13: Scan | AA13: Scan | AB13: Scan | AC13: Scan | AD13: Scan | AE13: Scan | AF13: Pop | AH13: =COUNT($B13:$AF13) -> 2 | AI13: =COUNTIF($B13:$AF13,"Pop") -> 1 | AJ13: =COUNTIF($B13:$AF13,"Scan") -> 28 | AK13: =SUM(AH13:AJ13) -> 31
A14: Type | B14: 17 | C14: 18 | D14: 19 | E14: 20 | F14: 21 | G14: Scan | H14: Scan | I14: Scan | J14: Scan | K14: Scan | L14: Pop | M14: Scan | N14: Scan | O14: Scan | P14: Scan | Q14: Scan | R14: Scan | S14: Scan | T14: Scan | U14: Scan | V14: Scan | W14: Scan | X14: Scan | Y14: Scan | Z14: Scan | AA14: Scan | AB14: Scan | AC14: Scan | AD14: Scan | AE14: Scan | AF14: Pop | AH14: =COUNT($B14:$AF14) -> 5 | AI14: =COUNTIF($B14:$AF14,"Pop") -> 2 | AJ14: =COUNTIF($B14:$AF14,"Scan") -> 24 | AK14: =SUM(AH14:AJ14) -> 31
A15: Stmt | B15: 27 | C15: 27 | D15: 27 | E15: 27 | F15: 27 | G15: Scan | H15: 22 | I15: 23 | J15: 25 | K15: Scan | L15: 24 | M15: 24 | N15: 24 | O15: Scan | P15: 26 | Q15: Pop | R15: Scan | S15: 28 | T15: Scan | U15: Scan | V15: Scan | W15: Scan | X15: Scan | Y15: Scan | Z15: Scan | AA15: Scan | AB15: Scan | AC15: Scan | AD15: Scan | AE15: Scan | AF15: Pop | AH15: =COUNT($B15:$AF15) -> 13 | AI15: =COUNTIF($B15:$AF15,"Pop") -> 2 | AJ15: =COUNTIF($B15:$AF15,"Scan") -> 16 | AK15: =SUM(AH15:AJ15) -> 31
A16: ForStmt | B16: Pop | C16: Pop | D16: Pop | E16: Pop | F16: Pop | G16: Scan | H16: 29 | I16: Pop | J16: Pop | K16: Scan | L16: Pop | M16: Pop | N16: Pop | O16: Scan | P16: Pop | Q16: Pop | R16: Scan | S16: Pop | T16: Scan | U16: Scan | V16: Scan | W16: Scan | X16: Scan | Y16: Scan | Z16: Scan | AA16: Scan | AB16: Scan | AC16: Scan | AD16: Scan | AE16: Scan | AF16: Pop | AH16: =COUNT($B16:$AF16) -> 1 | AI16: =COUNTIF($B16:$AF16,"Pop") -> 14 | AJ16: =COUNTIF($B16:$AF16,"Scan") -> 16 | AK16: =SUM(AH16:AJ16) -> 31
A17: OptExpr | B17: Scan | C17: Scan | D17: Scan | E17: Scan | F17: Scan | G17: Scan | H17: Scan | I17: Scan | J17: Scan | K17: Scan | L17: 30 | M17: 30 | N17: 30 | O17: 31 | P17: Scan | Q17: Scan | R17: Scan | S17: 31 | T17: Scan | U17: Scan | V17: Scan | W17: Scan | X17: Scan | Y17: Scan | Z17: Scan | AA17: Scan | AB17: Scan | AC17: Scan | AD17: Scan | AE17: Scan | AF17: Pop | AH17: =COUNT($B17:$AF17) -> 5 | AI17: =COUNTIF($B17:$AF17,"Pop") -> 1 | AJ17: =COUNTIF($B17:$AF17,"Scan") -> 25 | AK17: =SUM(AH17:AJ17) -> 31
A18: WhileStmt | B18: Pop | C18: Pop | D18: Pop | E18: Pop | F18: Pop | G18: Scan | H18: Pop | I18: 32 | J18: Pop | K18: Scan | L18: Pop | M18: Pop | N18: Pop | O18: Scan | P18: Pop | Q18: Pop | R18: Scan | S18: Pop | T18: Scan | U18: Scan | V18: Scan | W18: Scan | X18: Scan | Y18: Scan | Z18: Scan | AA18: Scan | AB18: Scan | AC18: Scan | AD18: Scan | AE18: Scan | AF18: Pop | AH18: =COUNT($B18:$AF18) -> 1 | AI18: =COUNTIF($B18:$AF18,"Pop") -> 14 | AJ18: =COUNTIF($B18:$AF18,"Scan") -> 16 | AK18: =SUM(AH18:AJ18) -> 31
A19: IfStmt | B19: Pop | C19: Pop | D19: Pop | E19: Pop | F19: Pop | G19: Scan | H19: Pop | I19: Pop | J19: 33 | K19: Scan | L19: Pop | M19: Pop | N19: Pop | O19: Scan | P19: Pop | Q19: Pop | R19: Scan | S19: Pop | T19: Scan | U19: Scan | V19: Scan | W19: Scan | X19: Scan | Y19: Scan | Z19: Scan | AA19: Scan | AB19: Scan | AC19: Scan | AD19: Scan | AE19: Scan | AF19: Pop | AH19: =COUNT($B19:$AF19) -> 1 | AI19: =COUNTIF($B19:$AF19,"Pop") -> 14 | AJ19: =COUNTIF($B19:$AF19,"Scan") -> 16 | AK19: =SUM(AH19:AJ19) -> 31
A20: ElsePart | B20: 35 | C20: 35 | D20: 35 | E20: 35 | F20: 35 | G20: Scan | H20: 35 | I20: 35 | J20: 35 | K20: 34 | L20: 35 | M20: 35 | N20: 35 | O20: Scan | P20: 35 | Q20: 35 | R20: Scan | S20: 35 | T20: Scan | U20: Scan | V20: Scan | W20: Scan | X20: Scan | Y20: Scan | Z20: Scan | AA20: Scan | AB20: Scan | AC20: Scan | AD20: Scan | AE20: Scan | AF20: Pop | AH20: =COUNT($B20:$AF20) -> 15 | AI20: =COUNTIF($B20:$AF20,"Pop") -> 1 | AJ20: =COUNTIF($B20:$AF20,"Scan") -> 15 | AK20: =SUM(AH20:AJ20) -> 31
A21: CompStmt | B21: Pop | C21: Pop | D21: Pop | E21: Pop | F21: Pop | G21: Scan | H21: Pop | I21: Pop | J21: Pop | K21: Pop | L21: Pop | M21: Pop | N21: Pop | O21: Scan | P21: 36 | Q21: Pop | R21: Scan | S21: Pop | T21: Scan | U21: Scan | V21: Scan | W21: Scan | X21: Scan | Y21: Scan | Z21: Scan | AA21: Scan | AB21: Scan | AC21: Scan | AD21: Scan | AE21: Scan | AF21: Pop | AH21: =COUNT($B21:$AF21) -> 1 | AI21: =COUNTIF($B21:$AF21,"Pop") -> 15 | AJ21: =COUNTIF($B21:$AF21,"Scan") -> 15 | AK21: =SUM(AH21:AJ21) -> 31
A22: StmtList | B22: 37 | C22: 37 | D22: 37 | E22: 37 | F22: 37 | G22: Scan | H22: 37 | I22: 37 | J22: 37 | K22: Scan | L22: 37 | M22: 37 | N22: 37 | O22: Scan | P22: 37 | Q22: 38 | R22: Scan | S22: 37 | T22: Scan | U22: Scan | V22: Scan | W22: Scan | X22: Scan | Y22: Scan | Z22: Scan | AA22: Scan | AB22: Scan | AC22: Scan | AD22: Scan | AE22: Scan | AF22: Pop | AH22: =COUNT($B22:$AF22) -> 14 | AI22: =COUNTIF($B22:$AF22,"Pop") -> 1 | AJ22: =COUNTIF($B22:$AF22,"Scan") -> 16 | AK22: =SUM(AH22:AJ22) -> 31
A23: Expr | B23: Scan | C23: Scan | D23: Scan | E23: Scan | F23: Scan | G23: Scan | H23: Scan | I23: Scan | J23: Scan | K23: Scan | L23: 39 | M23: 40 | N23: 41 | O23: Pop | P23: Scan | Q23: Scan | R23: Scan | S23: Pop | T23: Scan | U23: Scan | V23: Scan | W23: Scan | X23: Scan | Y23: Scan | Z23: Scan | AA23: Scan | AB23: Scan | AC23: Scan | AD23: Scan | AE23: Scan | AF23: Pop | AH23: =COUNT($B23:$AF23) -> 3 | AI23: =COUNTIF($B23:$AF23,"Pop") -> 3 | AJ23: =COUNTIF($B23:$AF23,"Scan") -> 25 | AK23: =SUM(AH23:AJ23) -> 31
A24: ExprRest | B24: Scan | C24: Scan | D24: Scan | E24: Scan | F24: Scan | G24: Scan | H24: Scan | I24: Scan | J24: Scan | K24: Scan | L24: Scan | M24: Scan | N24: Scan | O24: 43 | P24: Scan | Q24: Scan | R24: Scan | S24: 43 | T24: 42 | U24: 43 | V24: 43 | W24: 43 | X24: 43 | Y24: 43 | Z24: 43 | AA24: 43 | AB24: 43 | AC24: 43 | AD24: 43 | AE24: 43 | AF24: Pop | AH24: =COUNT($B24:$AF24) -> 14 | AI24: =COUNTIF($B24:$AF24,"Pop") -> 1 | AJ24: =COUNTIF($B24:$AF24,"Scan") -> 16 | AK24: =SUM(AH24:AJ24) -> 31
A25: RvTail | B25: Scan | C25: Scan | D25: Scan | E25: Scan | F25: Scan | G25: Scan | H25: Scan | I25: Scan | J25: Scan | K25: Scan | L25: Scan | M25: Scan | N25: Scan | O25: 44 | P25: Scan | Q25: Scan | R25: Scan | S25: 44 | T25: Scan | U25: 44 | V25: 44 | W25: 44 | X25: 44 | Y25: 44 | Z25: 44 | AA25: 44 | AB25: 44 | AC25: 44 | AD25: 44 | AE25: 44 | AF25: Pop | AH25: =COUNT($B25:$AF25) -> 13 | AI25: =COUNTIF($B25:$AF25,"Pop") -> 1 | AJ25: =COUNTIF($B25:$AF25,"Scan") -> 17 | AK25: =SUM(AH25:AJ25) -> 31
A26: Rvalue' | B26: Scan | C26: Scan | D26: Scan | E26: Scan | F26: Scan | G26: Scan | H26: Scan | I26: Scan | J26: Scan | K26: Scan | L26: Scan | M26: Scan | N26: Scan | O26: 46 | P26: Scan | Q26: Scan | R26: Scan | S26: 46 | T26: Scan | U26: 45 | V26: 45 | W26: 45 | X26: 45 | Y26: 45 | Z26: 45 | AA26: 45 | AB26: Scan | AC26: Scan | AD26: Scan | AE26: Scan | AF26: Pop | AH26: =COUNT($B26:$AF26) -> 9 | AI26: =COUNTIF($B26:$AF26,"Pop") -> 1 | AJ26: =COUNTIF($B26:$AF26,"Scan") -> 21 | AK26: =SUM(AH26:AJ26) -> 31
A27: Compare | B27: Scan | C27: Scan | D27: Scan | E27: Scan | F27: Scan | G27: Scan | H27: Scan | I27: Scan | J27: Scan | K27: Scan | L27: Pop | M27: Pop | N27: Pop | O27: Scan | P27: Scan | Q27: Scan | R27: Scan | S27: Scan | T27: Scan | U27: 47 | V27: 48 | W27: 49 | X27: 50 | Y27: 51 | Z27: 52 | AA27: 53 | AB27: Scan | AC27: Scan | AD27: Scan | AE27: Scan | AF27: Pop | AH27: =COUNT($B27:$AF27) -> 7 | AI27: =COUNTIF($B27:$AF27,"Pop") -> 4 | AJ27: =COUNTIF($B27:$AF27,"Scan") -> 20 | AK27: =SUM(AH27:AJ27) -> 31
A28: Mag | B28: Scan | C28: Scan | D28: Scan | E28: Scan | F28: Scan | G28: Scan | H28: Scan | I28: Scan | J28: Scan | K28: Scan | L28: 54 | M28: 54 | N28: 54 | O28: Pop | P28: Scan | Q28: Scan | R28: Scan | S28: Pop | T28: Scan | U28: Pop | V28: Pop | W28: Pop | X28: Pop | Y28: Pop | Z28: Pop | AA28: Pop | AB28: Scan | AC28: Scan | AD28: Scan | AE28: Scan | AF28: Pop | AH28: =COUNT($B28:$AF28) -> 3 | AI28: =COUNTIF($B28:$AF28,"Pop") -> 10 | AJ28: =COUNTIF($B28:$AF28,"Scan") -> 18 | AK28: =SUM(AH28:AJ28) -> 31
A29: Mag' | B29: Scan | C29: Scan | D29: Scan | E29: Scan | F29: Scan | G29: Scan | H29: Scan | I29: Scan | J29: Scan | K29: Scan | L29: Scan | M29: Scan | N29: Scan | O29: 57 | P29: Scan | Q29: Scan | R29: Scan | S29: 57 | T29: Scan | U29: 57 | V29: 57 | W29: 57 | X29: 57 | Y29: 57 | Z29: 57 | AA29: 57 | AB29: 55 | AC29: 56 | AD29: Scan | AE29: Scan | AF29: Pop | AH29: =COUNT($B29:$AF29) -> 11 | AI29: =COUNTIF($B29:$AF29,"Pop") -> 1 | AJ29: =COUNTIF($B29:$AF29,"Scan") -> 19 | AK29: =SUM(AH29:AJ29) -> 31
A30: Term | B30: Scan | C30: Scan | D30: Scan | E30: Scan | F30: Scan | G30: Scan | H30: Scan | I30: Scan | J30: Scan | K30: Scan | L30: 58 | M30: 58 | N30: 58 | O30: Pop | P30: Scan | Q30: Scan | R30: Scan | S30: Pop | T30: Scan | U30: Pop | V30: Pop | W30: Pop | X30: Pop | Y30: Pop | Z30: Pop | AA30: Pop | AB30: Pop | AC30: Pop | AD30: Scan | AE30: Scan | AF30: Pop | AH30: =COUNT($B30:$AF30) -> 3 | AI30: =COUNTIF($B30:$AF30,"Pop") -> 12 | AJ30: =COUNTIF($B30:$AF30,"Scan") -> 16 | AK30: =SUM(AH30:AJ30) -> 31
A31: Term' | B31: Scan | C31: Scan | D31: Scan | E31: Scan | F31: Scan | G31: Scan | H31: Scan | I31: Scan | J31: Scan | K31: Scan | L31: Scan | M31: Scan | N31: Scan | O31: 61 | P31: Scan | Q31: Scan | R31: Scan | S31: 61 | T31: Scan | U31: 61 | V31: 61 | W31: 61 | X31: 61 | Y31: 61 | Z31: 61 | AA31: 61 | AB31: 61 | AC31: 61 | AD31: 59 | AE31: 60 | AF31: Pop | AH31: =COUNT($B31:$AF31) -> 13 | AI31: =COUNTIF($B31:$AF31,"Pop") -> 1 | AJ31: =COUNTIF($B31:$AF31,"Scan") -> 17 | AK31: =SUM(AH31:AJ31) -> 31
A32: Factor | B32: Scan | C32: Scan | D32: Scan | E32: Scan | F32: Scan | G32: Scan | H32: Scan | I32: Scan | J32: Scan | K32: Scan | L32: 63 | M32: 64 | N32: 62 | O32: Pop | P32: Scan | Q32: Scan | R32: Scan | S32: Pop | T32: Scan | U32: Pop | V32: Pop | W32: Pop | X32: Pop | Y32: Pop | Z32: Pop | AA32: Pop | AB32: Pop | AC32: Pop | AD32: Pop | AE32: Pop | AF32: Pop | AH32: =COUNT($B32:$AF32) -> 3 | AI32: =COUNTIF($B32:$AF32,"Pop") -> 14 | AJ32: =COUNTIF($B32:$AF32,"Scan") -> 14 | AK32: =SUM(AH32:AJ32) -> 31
AG33: Total | AH33: =SUM(AH5:AH32) -> 163 | AI33: =SUM(AI5:AI32) -> 134 | AJ33: =SUM(AJ5:AJ32) -> 571 | AK33: =SUM(AK5:AK32) -> 868
A35: Checks
A36: Error boxes (Pop + Scan) - handwritten PDF states 705 | J36: =AI33+AJ33 -> 705 | K36: 705 | L36: =IF(J36=K36,"OK","CHECK") -> OK
A37: Boxes in the table (28 rows x 31 columns) | J37: =AK33 -> 868 | K37: 868 | L37: =IF(J37=K37,"OK","CHECK") -> OK
A38: Boxes holding a production number | J38: =AH33 -> 163 | K38: 163 | L38: =IF(J38=K38,"OK","CHECK") -> OK
A39: Blue = expected value from the handwritten solution (Part E). Boxes holding two productions: 0 (the grammar is LL(1)). A token outside the grammar ("other": Wapas, True, [ ], ++ ... quoted literals) is Scan in every row, so it has no column here.

Sheet Panic Recovery
A1: Panic-mode error recovery (SCAN / POP) driven by FIRST and FOLLOW
A2: Every error is recorded (line, column, token, expected set) and the parser recovers without crashing, so the rest of the program is still checked. An input with syntax errors is never accepted.
A4: Recovery rules (Part D)
A5: Situation (stack top X, lookahead a) | B5: Table box | C5: Action | D5: Why
A6: X is a variable, M[X,a] = production | B6: number | C6: Expand: pop X, push the right side R->L | D6: normal parsing
A7: X is a variable, M[X,a] empty and a in FOLLOW(X) (or a = $) | B7: Pop | C7: POP X (discard X from the stack), resume parsing after X | D7: a is a legal token for the symbol that follows X, so X is assumed missing/empty
A8: X is a variable, M[X,a] empty and a not in FIRST(X) U FOLLOW(X) | B8: Scan | C8: SCAN a (discard a from the input, read the next token), repeat | D8: a cannot start X nor follow it: skip tokens until one of FIRST(X) U FOLLOW(X) appears
A9: X is a terminal and X = a | B9: - | C9: match: pop X, advance input | D9: -
A10: X is a terminal and X != a | B10: - | C10: POP X (treated as missing, "expected X"); if a is not a grammar token -> SCAN a | D10: insert-the-missing-token recovery
A11: X = $ but input not finished | B11: - | C11: SCAN the extra tokens | D11: nothing more can be derived
A12: Both stack and input are $ | B12: - | C12: ACCEPT only if the error count is 0, otherwise REJECT ("parsed with N errors") | D12: an input with syntax errors is never accepted
A15: Recovery points per non-terminal (read directly from Parse Table and the FIRST/FOLLOW sets)
A16: Non-terminal A | B16: POP on (empty box in FOLLOW(A) or $) | C16: FIRST(A) - SCAN stops here | D16: Pop boxes | E16: Scan boxes | F16: Production boxes
A17: Program | B17: $ | C17: { Adadi, Ashriya, Harf, Matn, Mantiqi } | D17: =COUNTIF('Parse Table'!$B$5:$AF$5,"Pop") -> 1 | E17: =COUNTIF('Parse Table'!$B$5:$AF$5,"Scan") -> 25 | F17: =COUNT('Parse Table'!$B$5:$AF$5) -> 5
A18: ProgTail | B18: $ | C18: { Marqazi, ID } | D18: =COUNTIF('Parse Table'!$B$6:$AF$6,"Pop") -> 1 | E18: =COUNTIF('Parse Table'!$B$6:$AF$6,"Scan") -> 28 | F18: =COUNT('Parse Table'!$B$6:$AF$6) -> 2
A19: FuncRest | B19: $ | C19: { ID } | D19: =COUNTIF('Parse Table'!$B$7:$AF$7,"Pop") -> 1 | E19: =COUNTIF('Parse Table'!$B$7:$AF$7,"Scan") -> 29 | F19: =COUNT('Parse Table'!$B$7:$AF$7) -> 1
A20: ArgList | B20: ), $ | C20: { Adadi, Ashriya, Harf, Matn, Mantiqi } | D20: =COUNTIF('Parse Table'!$B$8:$AF$8,"Pop") -> 2 | E20: =COUNTIF('Parse Table'!$B$8:$AF$8,"Scan") -> 24 | F20: =COUNT('Parse Table'!$B$8:$AF$8) -> 5
A21: ArgList' | B21: $ | C21: { ,, ε } | D21: =COUNTIF('Parse Table'!$B$9:$AF$9,"Pop") -> 1 | E21: =COUNTIF('Parse Table'!$B$9:$AF$9,"Scan") -> 28 | F21: =COUNT('Parse Table'!$B$9:$AF$9) -> 2
A22: Arg | B22: ), ,, $ | C22: { Adadi, Ashriya, Harf, Matn, Mantiqi } | D22: =COUNTIF('Parse Table'!$B$10:$AF$10,"Pop") -> 3 | E22: =COUNTIF('Parse Table'!$B$10:$AF$10,"Scan") -> 23 | F22: =COUNT('Parse Table'!$B$10:$AF$10) -> 5
A23: Declaration | B23: for, while, Agar, ID, NUM, (, {, }, ::, $ | C23: { Adadi, Ashriya, Harf, Matn, Mantiqi } | D23: =COUNTIF('Parse Table'!$B$11:$AF$11,"Pop") -> 10 | E23: =COUNTIF('Parse Table'!$B$11:$AF$11,"Scan") -> 16 | F23: =COUNT('Parse Table'!$B$11:$AF$11) -> 5
A24: IdentList | B24: ::, $ | C24: { ID } | D24: =COUNTIF('Parse Table'!$B$12:$AF$12,"Pop") -> 2 | E24: =COUNTIF('Parse Table'!$B$12:$AF$12,"Scan") -> 28 | F24: =COUNT('Parse Table'!$B$12:$AF$12) -> 1
A25: IdentList' | B25: $ | C25: { ,, ε } | D25: =COUNTIF('Parse Table'!$B$13:$AF$13,"Pop") -> 1 | E25: =COUNTIF('Parse Table'!$B$13:$AF$13,"Scan") -> 28 | F25: =COUNT('Parse Table'!$B$13:$AF$13) -> 2
A26: Type | B26: ID, $ | C26: { Adadi, Ashriya, Harf, Matn, Mantiqi } | D26: =COUNTIF('Parse Table'!$B$14:$AF$14,"Pop") -> 2 | E26: =COUNTIF('Parse Table'!$B$14:$AF$14,"Scan") -> 24 | F26: =COUNT('Parse Table'!$B$14:$AF$14) -> 5
A27: Stmt | B27: }, $ | C27: { Adadi, Ashriya, Harf, Matn, Mantiqi, for, while, Agar, ID, NUM, (, {, :: } | D27: =COUNTIF('Parse Table'!$B$15:$AF$15,"Pop") -> 2 | E27: =COUNTIF('Parse Table'!$B$15:$AF$15,"Scan") -> 16 | F27: =COUNT('Parse Table'!$B$15:$AF$15) -> 13
A28: ForStmt | B28: Adadi, Ashriya, Harf, Matn, Mantiqi, while, Agar, ID, NUM, (, {, }, ::, $ | C28: { for } | D28: =COUNTIF('Parse Table'!$B$16:$AF$16,"Pop") -> 14 | E28: =COUNTIF('Parse Table'!$B$16:$AF$16,"Scan") -> 16 | F28: =COUNT('Parse Table'!$B$16:$AF$16) -> 1
A29: OptExpr | B29: $ | C29: { ID, NUM, (, ε } | D29: =COUNTIF('Parse Table'!$B$17:$AF$17,"Pop") -> 1 | E29: =COUNTIF('Parse Table'!$B$17:$AF$17,"Scan") -> 25 | F29: =COUNT('Parse Table'!$B$17:$AF$17) -> 5
A30: WhileStmt | B30: Adadi, Ashriya, Harf, Matn, Mantiqi, for, Agar, ID, NUM, (, {, }, ::, $ | C30: { while } | D30: =COUNTIF('Parse Table'!$B$18:$AF$18,"Pop") -> 14 | E30: =COUNTIF('Parse Table'!$B$18:$AF$18,"Scan") -> 16 | F30: =COUNT('Parse Table'!$B$18:$AF$18) -> 1
A31: IfStmt | B31: Adadi, Ashriya, Harf, Matn, Mantiqi, for, while, ID, NUM, (, {, }, ::, $ | C31: { Agar } | D31: =COUNTIF('Parse Table'!$B$19:$AF$19,"Pop") -> 14 | E31: =COUNTIF('Parse Table'!$B$19:$AF$19,"Scan") -> 16 | F31: =COUNT('Parse Table'!$B$19:$AF$19) -> 1
A32: ElsePart | B32: $ | C32: { Wagarna, ε } | D32: =COUNTIF('Parse Table'!$B$20:$AF$20,"Pop") -> 1 | E32: =COUNTIF('Parse Table'!$B$20:$AF$20,"Scan") -> 15 | F32: =COUNT('Parse Table'!$B$20:$AF$20) -> 15
A33: CompStmt | B33: Adadi, Ashriya, Harf, Matn, Mantiqi, for, while, Agar, Wagarna, ID, NUM, (, }, ::, $ | C33: { { } | D33: =COUNTIF('Parse Table'!$B$21:$AF$21,"Pop") -> 15 | E33: =COUNTIF('Parse Table'!$B$21:$AF$21,"Scan") -> 15 | F33: =COUNT('Parse Table'!$B$21:$AF$21) -> 1
A34: StmtList | B34: $ | C34: { Adadi, Ashriya, Harf, Matn, Mantiqi, for, while, Agar, ID, NUM, (, {, ::, ε } | D34: =COUNTIF('Parse Table'!$B$22:$AF$22,"Pop") -> 1 | E34: =COUNTIF('Parse Table'!$B$22:$AF$22,"Scan") -> 16 | F34: =COUNT('Parse Table'!$B$22:$AF$22) -> 14
A35: Expr | B35: ), ::, $ | C35: { ID, NUM, ( } | D35: =COUNTIF('Parse Table'!$B$23:$AF$23,"Pop") -> 3 | E35: =COUNTIF('Parse Table'!$B$23:$AF$23,"Scan") -> 25 | F35: =COUNT('Parse Table'!$B$23:$AF$23) -> 3
A36: ExprRest | B36: $ | C36: { :=, ==, <, >, <=, >=, !=, <>, +, -, *, /, ε } | D36: =COUNTIF('Parse Table'!$B$24:$AF$24,"Pop") -> 1 | E36: =COUNTIF('Parse Table'!$B$24:$AF$24,"Scan") -> 16 | F36: =COUNT('Parse Table'!$B$24:$AF$24) -> 14
A37: RvTail | B37: $ | C37: { ==, <, >, <=, >=, !=, <>, +, -, *, /, ε } | D37: =COUNTIF('Parse Table'!$B$25:$AF$25,"Pop") -> 1 | E37: =COUNTIF('Parse Table'!$B$25:$AF$25,"Scan") -> 17 | F37: =COUNT('Parse Table'!$B$25:$AF$25) -> 13
A38: Rvalue' | B38: $ | C38: { ==, <, >, <=, >=, !=, <>, ε } | D38: =COUNTIF('Parse Table'!$B$26:$AF$26,"Pop") -> 1 | E38: =COUNTIF('Parse Table'!$B$26:$AF$26,"Scan") -> 21 | F38: =COUNT('Parse Table'!$B$26:$AF$26) -> 9
A39: Compare | B39: ID, NUM, (, $ | C39: { ==, <, >, <=, >=, !=, <> } | D39: =COUNTIF('Parse Table'!$B$27:$AF$27,"Pop") -> 4 | E39: =COUNTIF('Parse Table'!$B$27:$AF$27,"Scan") -> 20 | F39: =COUNT('Parse Table'!$B$27:$AF$27) -> 7
A40: Mag | B40: ), ::, ==, <, >, <=, >=, !=, <>, $ | C40: { ID, NUM, ( } | D40: =COUNTIF('Parse Table'!$B$28:$AF$28,"Pop") -> 10 | E40: =COUNTIF('Parse Table'!$B$28:$AF$28,"Scan") -> 18 | F40: =COUNT('Parse Table'!$B$28:$AF$28) -> 3
A41: Mag' | B41: $ | C41: { +, -, ε } | D41: =COUNTIF('Parse Table'!$B$29:$AF$29,"Pop") -> 1 | E41: =COUNTIF('Parse Table'!$B$29:$AF$29,"Scan") -> 19 | F41: =COUNT('Parse Table'!$B$29:$AF$29) -> 11
A42: Term | B42: ), ::, ==, <, >, <=, >=, !=, <>, +, -, $ | C42: { ID, NUM, ( } | D42: =COUNTIF('Parse Table'!$B$30:$AF$30,"Pop") -> 12 | E42: =COUNTIF('Parse Table'!$B$30:$AF$30,"Scan") -> 16 | F42: =COUNT('Parse Table'!$B$30:$AF$30) -> 3
A43: Term' | B43: $ | C43: { *, /, ε } | D43: =COUNTIF('Parse Table'!$B$31:$AF$31,"Pop") -> 1 | E43: =COUNTIF('Parse Table'!$B$31:$AF$31,"Scan") -> 17 | F43: =COUNT('Parse Table'!$B$31:$AF$31) -> 13
...

Sheet Dry Runs
A1: Dry runs
A2: Each row is one parser step: the stack top is on the left, M[A,a] is looked up in the Parse Table sheet, and a production is pushed right-to-left. Grey rows = terminal matches, white rows = table lookups, red rows = errors (recovered by POP or SCAN, see the Panic Recovery sheet), green = accept.
A4: Part 1
A5: Source program
B6: Adadi sum_val ( Adadi first_arg , Ashriya second_arg )
B7: {
B8: Adadi first_val, total_val ::
B9: first_val := first_arg + 2 * 3 ::
B10: total_val := first_val - 1 ::
B11: }
A12: Token stream (Phase 1 Token.txt mapped to terminals): | C12: Adadi ID ( Adadi ID , Ashriya ID ) { Adadi ID , ID :: ID := ID + NUM * NUM :: ID := ID - NUM :: } $
A14: Step | B14: Stack (top left) | C14: Input | D14: Production / Action | E14: Error
A15: 1 | B15: Program $ | C15: Adadi ID ( Adadi ID , Ashriya ID ) { Adadi ID , ID :: ID := ID + NUM * NUM :: ID := ID - NUM :: } $ | D15: M[Program,Adadi] = 1: Program → Adadi ProgTail
A16: 2 | B16: Adadi ProgTail $ | C16: Adadi ID ( Adadi ID , Ashriya ID ) { Adadi ID , ID :: ID := ID + NUM * NUM :: ID := ID - NUM :: } $ | D16: match Adadi
A17: 3 | B17: ProgTail $ | C17: ID ( Adadi ID , Ashriya ID ) { Adadi ID , ID :: ID := ID + NUM * NUM :: ID := ID - NUM :: } $ | D17: M[ProgTail,ID] = 7: ProgTail → FuncRest
A18: 4 | B18: FuncRest $ | C18: ID ( Adadi ID , Ashriya ID ) { Adadi ID , ID :: ID := ID + NUM * NUM :: ID := ID - NUM :: } $ | D18: M[FuncRest,ID] = 8: FuncRest → ID ( ArgList ) CompStmt
A19: 5 | B19: ID ( ArgList ) CompStmt $ | C19: ID ( Adadi ID , Ashriya ID ) { Adadi ID , ID :: ID := ID + NUM * NUM :: ID := ID - NUM :: } $ | D19: match ID
A20: 6 | B20: ( ArgList ) CompStmt $ | C20: ( Adadi ID , Ashriya ID ) { Adadi ID , ID :: ID := ID + NUM * NUM :: ID := ID - NUM :: } $ | D20: match (
A21: 7 | B21: ArgList ) CompStmt $ | C21: Adadi ID , Ashriya ID ) { Adadi ID , ID :: ID := ID + NUM * NUM :: ID := ID - NUM :: } $ | D21: M[ArgList,Adadi] = 9: ArgList → Arg ArgList'
A22: 8 | B22: Arg ArgList' ) CompStmt $ | C22: Adadi ID , Ashriya ID ) { Adadi ID , ID :: ID := ID + NUM * NUM :: ID := ID - NUM :: } $ | D22: M[Arg,Adadi] = 12: Arg → Type ID
A23: 9 | B23: Type ID ArgList' ) CompStmt $ | C23: Adadi ID , Ashriya ID ) { Adadi ID , ID :: ID := ID + NUM * NUM :: ID := ID - NUM :: } $ | D23: M[Type,Adadi] = 17: Type → Adadi
A24: 10 | B24: Adadi ID ArgList' ) CompStmt $ | C24: Adadi ID , Ashriya ID ) { Adadi ID , ID :: ID := ID + NUM * NUM :: ID := ID - NUM :: } $ | D24: match Adadi
A25: 11 | B25: ID ArgList' ) CompStmt $ | C25: ID , Ashriya ID ) { Adadi ID , ID :: ID := ID + NUM * NUM :: ID := ID - NUM :: } $ | D25: match ID
A26: 12 | B26: ArgList' ) CompStmt $ | C26: , Ashriya ID ) { Adadi ID , ID :: ID := ID + NUM * NUM :: ID := ID - NUM :: } $ | D26: M[ArgList',,] = 10: ArgList' → , Arg ArgList'
... A95: 81 | B95: $ | C95: $ | D95: accept
A96: Result: ACCEPT - stack and input both reduced to $ with 0 errors.
A98: Checks (live formulas vs the handwritten solution)
B99: Measure | C99: Counted here | D99: Handwritten PDF | E99: Status
B100: Parser steps | C100: =COUNT($A$15:$A$95) -> 81 | D100: 81 | E100: =IF(C100=D100,"OK","CHECK") -> OK
B101: Syntax errors (red rows) | C101: =COUNTIF($E$15:$E$95,"E*") -> 0 | D101: 0 | E101: =IF(C101=D101,"OK","CHECK") -> OK
B102: SCAN recoveries | C102: =COUNTIF($D$15:$D$95,"*SCAN*") -> 0 | D102: 0 | E102: =IF(C102=D102,"OK","CHECK") -> OK
B103: POP recoveries | C103: =COUNTIF($D$15:$D$95,"*POP*") -> 0 | D103: 0 | E103: =IF(C103=D103,"OK","CHECK") -> OK
A106: Part 2
A107: Source program
B108: Adadi Marqazi ()
B109: {
B110: Adadi first_val, ::
B111: first_val := 2 + ::
B112: }
A113: Token stream (Phase 1 Token.txt mapped to terminals): | C113: Adadi Marqazi ( ) { Adadi ID , :: ID := NUM + :: } $
...
